<?xml version="1.0"?>
<sdf version="1.10">

    <model name="wave_rover_4wd" canonical_link="telo">
        <!-- Telo robota -->
        <link name="telo">
            <collision name="collision">
                <geometry>
                    <box><size>2.0 1.0 0.5</size></box>
                </geometry>
            </collision>
            <visual name="visual">
                <geometry>
                   <box><size>2.0 1.0 0.5</size></box>
                </geometry>
                <material>
                    <ambient>0.0 0.0 1.0 1</ambient>
                    <diffuse>0.0 0.0 1.0 1</diffuse>
                    <specular>0.0 0.0 1.0 1</specular>
                </material>
            </visual>
        </link>

        <!-- Zadné ľavé koleso -->
        <link name="zadne_lave_koleso">
            <pose relative_to="telo">-0.5 0.6 0 -1.5707 0 0</pose>
            <collision name="collision">
                <geometry>
                    <cylinder><radius>0.4</radius><length>0.2</length></cylinder>
                </geometry>
            </collision>
            <visual name="visual">
                <geometry>
                   <cylinder><radius>0.4</radius><length>0.2</length></cylinder>
                </geometry>
                <material>
                    <ambient>1.0 0.0 0.0 1</ambient>
                    <diffuse>1.0 0.0 0.0 1</diffuse>
                    <specular>1.0 0.0 0.0 1</specular>
                </material>
            </visual>
        </link>

        <joint name="zadne_lave_koleso_zaves" type="revolute">
            <pose relative_to="zadne_lave_koleso"/>
            <parent>telo</parent>
            <child>zadne_lave_koleso</child>
            <axis>
                <xyz expressed_in="__model__">0 1 0</xyz>
                <limit>
                    <lower>-1.79769e+308</lower>
                    <upper>1.79769e+308</upper>
                </limit>
            </axis>
        </joint>

        <!-- Zadné pravé koleso -->
        <link name="zadne_prave_koleso">
            <pose relative_to="telo">-0.5 -0.6 0 -1.5707 0 0</pose>
            <collision name="collision">
                <geometry>
                    <cylinder><radius>0.4</radius><length>0.2</length></cylinder>
                </geometry>
            </collision>
            <visual name="visual">
                <geometry>
                   <cylinder><radius>0.4</radius><length>0.2</length></cylinder>
                </geometry>
                <material>
                    <ambient>1.0 0.0 0.0 1</ambient>
                    <diffuse>1.0 0.0 0.0 1</diffuse>
                    <specular>1.0 0.0 0.0 1</specular>
                </material>
            </visual>
        </link>

        <joint name="zadne_prave_koleso_zaves" type="revolute">
            <pose relative_to="zadne_prave_koleso"/>
            <parent>telo</parent>
            <child>zadne_prave_koleso</child>
            <axis>
                <xyz expressed_in="__model__">0 1 0</xyz>
                <limit>
                    <lower>-1.79769e+308</lower>
                    <upper>1.79769e+308</upper>
                </limit>
            </axis>
        </joint>

        <!-- Predné ľavé koleso -->
        <link name="predne_lave_koleso">
            <pose relative_to="telo">0.5 0.6 0 -1.5707 0 0</pose>
            <collision name="collision">
                <geometry>
                    <cylinder><radius>0.4</radius><length>0.2</length></cylinder>
                </geometry>
            </collision>
            <visual name="visual">
                <geometry>
                   <cylinder><radius>0.4</radius><length>0.2</length></cylinder>
                </geometry>
                <material>
                    <ambient>1.0 0.0 0.0 1</ambient>
                    <diffuse>1.0 0.0 0.0 1</diffuse>
                    <specular>1.0 0.0 0.0 1</specular>
                </material>
            </visual>
        </link>

        <joint name="predne_lave_koleso_zaves" type="revolute">
            <pose relative_to="predne_lave_koleso"/>
            <parent>telo</parent>
            <child>predne_lave_koleso</child>
            <axis>
                <xyz expressed_in="__model__">0 1 0</xyz>
                <limit>
                    <lower>-1.79769e+308</lower>
                    <upper>1.79769e+308</upper>
                </limit>
            </axis>
        </joint>

        <!-- Predné pravé koleso -->
        <link name="predne_prave_koleso">
            <pose relative_to="telo">0.5 -0.6 0 -1.5707 0 0</pose>
            <collision name="collision">
                <geometry>
                    <cylinder><radius>0.4</radius><length>0.2</length></cylinder>
                </geometry>
            </collision>
            <visual name="visual">
                <geometry>
                   <cylinder><radius>0.4</radius><length>0.2</length></cylinder>
                </geometry>
                <material>
                    <ambient>1.0 0.0 0.0 1</ambient>
                    <diffuse>1.0 0.0 0.0 1</diffuse>
                    <specular>1.0 0.0 0.0 1</specular>
                </material>
            </visual>
        </link>

        <joint name="predne_prave_koleso_zaves" type="revolute">
            <pose relative_to="predne_prave_koleso"/>
            <parent>telo</parent>
            <child>predne_prave_koleso</child>
            <axis>
                <xyz expressed_in="__model__">0 1 0</xyz>
                <limit>
                    <lower>-1.79769e+308</lower>
                    <upper>1.79769e+308</upper>
                </limit>
            </axis>
        </joint>

        <!-- Kamera -->

        <link name="camera_base">
            <pose relative_to="telo">0 0 0.6 0 0 0</pose>
            <collision name="collision">
                <geometry>
                    <box><size>0.05 0.05 0.05</size></box>
                </geometry>
            </collision>
            <visual name="visual">
                <geometry>
                   <box><size>0.1 0.1 0.1</size></box>
                </geometry>
                <material>
                    <ambient>0.5 0.5 0.5 1</ambient>
                    <diffuse>0.5 0.5 0.5 1</diffuse>
                    <specular>0.5 0.5 0.5 1</specular>
                </material>
            </visual>

            <sensor name="camera" type="camera">
                <pose>0 0 0 0 0 0</pose>
                <camera>
                    <horizontal_fov>1.047</horizontal_fov>
                    <image>
                        <width>640</width>
                        <height>480</height>
                        <format>R8G8B8</format>
                    </image>
                    <clip>
                        <near>0.1</near>
                        <far>100</far>
                    </clip>
                    <distortion>
                        <k1>1.578758331993112829e-01</k1>
                        <k2>-5.784303605943902360e-01</k2>
                        <k3>-8.740723680089258069e-03</k3>
                        <p1>1.359451618091441112e-03</p1>
                        <p2>1.640043376158566713e-01</p2>
                        <center>0.5 0.5</center>
                    </distortion>
                    <lens>
                        <type>pinhole</type>
                        <scale_to_hfov>false</scale_to_hfov>
                        <intrinsics>
                            <fx>4.970870507466349295e+02</fx>
                            <fy>4.976011127668800782e+02</fy>
                            <cx>3.168387473166100108e+02</cx>
                            <cy>2.342740555042151982e+02</cy>
                        <s>0.0</s>
                        </intrinsics>
                    </lens>
                </camera>
                <always_on>1</always_on>
                <update_rate>30</update_rate>
                <visualize>true</visualize>
                <topic>camera/image</topic>
            </sensor>
        </link>

        <joint name="camera_base_joint" type="fixed">
            <parent>telo</parent>
            <child>camera_base</child>
        </joint>



        <!-- Pluginy -->
        <plugin filename="gz-sim-sensors-system" name="gz::sim::systems::Sensors">
            <render_engine>ogre2</render_engine>
        </plugin>


        <plugin filename="gz-sim-diff-drive-system" name="gz::sim::systems::DiffDrive">
            <left_joint>zadne_lave_koleso_zaves</left_joint>
            <right_joint>zadne_prave_koleso_zaves</right_joint>
            <left_joint>predne_lave_koleso_zaves</left_joint>
            <right_joint>predne_prave_koleso_zaves</right_joint>
            <wheel_separation>1.2</wheel_separation>
            <wheel_radius>0.4</wheel_radius>
            <odom_publish_frequency>1</odom_publish_frequency>
            <topic>cmd_vel</topic>
            <odom_topic>odom</odom_topic>
            <tf_topic>tf</tf_topic>
            <frame_id>odom</frame_id>
            <child_frame_id>telo</child_frame_id>
        </plugin>

        <plugin filename="gz-sim-joint-state-publisher-system"
            name="gz::sim::systems::JointStatePublisher">
            <topic>joint_states</topic>
             <publish_frequency>1</publish_frequency>
            <joint_name>zadne_lave_koleso_zaves</joint_name>
            <joint_name>zadne_prave_koleso_zaves</joint_name>
            <joint_name>predne_lave_koleso_zaves</joint_name>
            <joint_name>predne_prave_koleso_zaves</joint_name>
            <joint_name>camera_base_joint</joint_name>
        </plugin>

        <plugin filename="gz-sim-pose-publisher-system"
                name="gz::sim::systems::PosePublisher">
            <publish_link_pose>true</publish_link_pose>
            <publish_model_pose>true</publish_model_pose>
            <publish_nested_model_pose>true</publish_nested_model_pose>
            <use_sim_time>true</use_sim_time>
            <topic>/tf</topic>
        </plugin>

    </model>
</sdf>